Workbook

Sheet 0. Yönetici Özeti
A1: Finansman Şirketleri Ticari Kredi Analizi – Yönetici Özeti
A2: Analiz Dönemi: Haziran 2024 – Nisan 2026 | Birim: Milyon TL | Kaynak: TCMB - BDDK
A4: GENEL GÖRÜNÜM
A5: Dönem Başı Toplam Kredi | D5: ='2. İstatistikler'!B10 -> 117010.9
A6: Dönem Sonu Toplam Kredi | D6: ='2. İstatistikler'!B11 -> 278734.33
A7: Toplam Büyüme (%) | D7: ='3. Büyüme Analizi'!B7 -> 138.21227
A8: Haftalık Ort. Büyüme (%) | D8: ='3. Büyüme Analizi'!B8 -> 0.94795726
A9: Dönem Ortalaması | D9: ='2. İstatistikler'!B7 -> 185450.89
A11: TL / YP YAPISI | D11: TL | E11: YP
A12: Dönem Başı Payı (%) | D12: ='5. TL-YP Analizi'!B10 -> 83.779142 | E12: ='5. TL-YP Analizi'!C10 -> 16.220858
A13: Dönem Sonu Payı (%) | D13: ='5. TL-YP Analizi'!B11 -> 87.28003 | E13: ='5. TL-YP Analizi'!C11 -> 12.71997
A14: Ortalama Pay (%) | D14: ='5. TL-YP Analizi'!B12 -> 85.390351 | E14: ='5. TL-YP Analizi'!C12 -> 14.609649
A15: Pay Değişimi (Puan) | D15: ='5. TL-YP Analizi'!B15 -> 3.5008887 | E15: ='5. TL-YP Analizi'!C15 -> -3.5008887
A16: TL-YP Korelasyonu | D16: ='5. TL-YP Analizi'!D5 -> 0.91775034
A18: MEVSİMSELLİK
A19: En Yüksek Sezon (Ay)
A20: En Düşük Sezon (Ay)
A21: En Yüksek Endeks
A22: En Düşük Endeks
A24: 12 AYLIK TAHMİN
A25: Model
A26: Nisan 2027 Tahmini
A27: Alt Sınır (%80)
A28: Üst Sınır (%80)
A29: Beklenen Büyüme (%)

Sheet 1. Ham Veri
A1: Tarih | B1: Toplam | C1: TL | D1: YP | E1: Yıl | F1: Ay | G1: Haftalık Değişim (%) | H1: TL Payı (%) | I1: YP Payı (%)
A2: 28-06-2024 | B2: 117010.9 | C2: 98030.73 | D2: 18980.173 | E2: =YEAR(A2) -> 2024 | F2: =MONTH(A2) -> 6 | H2: =C2/B2*100 -> 83.779142 | I2: =D2/B2*100 -> 16.220858
A3: 05-07-2024 | B3: 114932.29 | C3: 96041.429 | D3: 18890.864 | E3: =YEAR(A3) -> 2024 | F3: =MONTH(A3) -> 7 | G3: =(B3-B2)/B2*100 -> -1.7764242 | H3: =C3/B3*100 -> 83.563485 | I3: =D3/B3*100 -> 16.436515
A4: 12-07-2024 | B4: 115625.71 | C4: 96172.502 | D4: 19453.208 | E4: =YEAR(A4) -> 2024 | F4: =MONTH(A4) -> 7 | G4: =(B4-B3)/B3*100 -> 0.60332652 | H4: =C4/B4*100 -> 83.175707 | I4: =D4/B4*100 -> 16.824293
A5: 19-07-2024 | B5: 116662.35 | C5: 96978.198 | D5: 19684.157 | E5: =YEAR(A5) -> 2024 | F5: =MONTH(A5) -> 7 | G5: =(B5-B4)/B4*100 -> 0.89655233 | H5: =C5/B5*100 -> 83.127242 | I5: =D5/B5*100 -> 16.872758
A6: 26-07-2024 | B6: 119109.59 | C6: 99718.083 | D6: 19391.502 | E6: =YEAR(A6) -> 2024 | F6: =MONTH(A6) -> 7 | G6: =(B6-B5)/B5*100 -> 2.0977032 | H6: =C6/B6*100 -> 83.719612 | I6: =D6/B6*100 -> 16.280388
A7: 02-08-2024 | B7: 120109.59 | C7: 100379.91 | D7: 19729.672 | E7: =YEAR(A7) -> 2024 | F7: =MONTH(A7) -> 8 | G7: =(B7-B6)/B6*100 -> 0.839563 | H7: =C7/B7*100 -> 83.573607 | I7: =D7/B7*100 -> 16.426393
A8: 09-08-2024 | B8: 120407.13 | C8: 100152.51 | D8: 20254.622 | E8: =YEAR(A8) -> 2024 | F8: =MONTH(A8) -> 8 | G8: =(B8-B7)/B7*100 -> 0.24773044 | H8: =C8/B8*100 -> 83.178221 | I8: =D8/B8*100 -> 16.821779
A9: 16-08-2024 | B9: 120243.96 | C9: 99771.962 | D9: 20471.995 | E9: =YEAR(A9) -> 2024 | F9: =MONTH(A9) -> 8 | G9: =(B9-B8)/B8*100 -> -0.13552021 | H9: =C9/B9*100 -> 82.974616 | I9: =D9/B9*100 -> 17.025384
A10: 23-08-2024 | B10: 121657.74 | C10: 100670.01 | D10: 20987.725 | E10: =YEAR(A10) -> 2024 | F10: =MONTH(A10) -> 8 | G10: =(B10-B9)/B9*100 -> 1.1757597 | H10: =C10/B10*100 -> 82.748549 | I10: =D10/B10*100 -> 17.251451
A11: 30-08-2024 | B11: 125053.04 | C11: 103837.22 | D11: 21215.821 | E11: =YEAR(A11) -> 2024 | F11: =MONTH(A11) -> 8 | G11: =(B11-B10)/B10*100 -> 2.7908665 | H11: =C11/B11*100 -> 83.034542 | I11: =D11/B11*100 -> 16.965458
A12: 06-09-2024 | B12: 123406.05 | C12: 102457.94 | D12: 20948.108 | E12: =YEAR(A12) -> 2024 | F12: =MONTH(A12) -> 9 | G12: =(B12-B11)/B11*100 -> -1.3170355 | H12: =C12/B12*100 -> 83.025056 | I12: =D12/B12*100 -> 16.974944
A13: 13-09-2024 | B13: 123318.52 | C13: 102559.99 | D13: 20758.531 | E13: =YEAR(A13) -> 2024 | F13: =MONTH(A13) -> 9 | G13: =(B13-B12)/B12*100 -> -0.0709244 | H13: =C13/B13*100 -> 83.166737 | I13: =D13/B13*100 -> 16.833263
A14: 20-09-2024 | B14: 124025.6 | C14: 102934.88 | D14: 21090.723 | E14: =YEAR(A14) -> 2024 | F14: =MONTH(A14) -> 9 | G14: =(B14-B13)/B13*100 -> 0.57337615 | H14: =C14/B14*100 -> 82.994864 | I14: =D14/B14*100 -> 17.005136
... A95: 10-04-2026 | B95: 278734.33 | C95: 243279.41 | D95: 35454.923 | E95: =YEAR(A95) -> 2026 | F95: =MONTH(A95) -> 4 | G95: =(B95-B94)/B94*100 -> -0.20548157 | H95: =C95/B95*100 -> 87.28003 | I95: =D95/B95*100 -> 12.71997

Sheet 2. İstatistikler
A1: Finansman Şirketleri - Genel İstatistikler (Milyon TL)
A3: İstatistik | B3: Toplam | C3: TL | D3: YP
A4: Gözlem Sayısı | B4: =ROWS('1. Ham Veri'!B2:B95) -> 94 | C4: =ROWS('1. Ham Veri'!C2:C95) -> 94 | D4: =ROWS('1. Ham Veri'!D2:D95) -> 94
A5: Minimum | B5: =MIN('1. Ham Veri'!B2:B95) -> 114932.29 | C5: =MIN('1. Ham Veri'!C2:C95) -> 96041.429 | D5: =MIN('1. Ham Veri'!D2:D95) -> 18890.864
A6: Maksimum | B6: =MAX('1. Ham Veri'!B2:B95) -> 279308.26 | C6: =MAX('1. Ham Veri'!C2:C95) -> 244250.31 | D6: =MAX('1. Ham Veri'!D2:D95) -> 35454.923
A7: Ortalama | B7: =AVERAGE('1. Ham Veri'!B2:B95) -> 185450.89 | C7: =AVERAGE('1. Ham Veri'!C2:C95) -> 158938.66 | D7: =AVERAGE('1. Ham Veri'!D2:D95) -> 26512.225
A8: Medyan | B8: =MEDIAN('1. Ham Veri'!B2:B95) -> 176483.89 | C8: =MEDIAN('1. Ham Veri'!C2:C95) -> 150015.42 | D8: =MEDIAN('1. Ham Veri'!D2:D95) -> 26701.175
A9: Std. Sapma | B9: =STDEV('1. Ham Veri'!B2:B95) -> 52774.555 | C9: =STDEV('1. Ham Veri'!C2:C95) -> 47513.359 | D9: =STDEV('1. Ham Veri'!D2:D95) -> 5680.1481
A10: Dönem Başı | B10: ='1. Ham Veri'!B2 -> 117010.9 | C10: ='1. Ham Veri'!C2 -> 98030.73 | D10: ='1. Ham Veri'!D2 -> 18980.173
A11: Dönem Sonu | B11: ='1. Ham Veri'!B95 -> 278734.33 | C11: ='1. Ham Veri'!C95 -> 243279.41 | D11: ='1. Ham Veri'!D95 -> 35454.923
A12: Toplam Değişim (%) | B12: =(B11-B10)/B10*100 -> 138.21227 | C12: =(C11-C10)/C10*100 -> 148.16648 | D12: =(D11-D10)/D10*100 -> 86.799788

Sheet 3. Büyüme Analizi
A1: Finansman Şirketleri - Büyüme Analizi
A3: Dönem | B3: Toplam | C3: TL | D3: YP
A4: Dönem Başı (Haz 2024) | B4: ='1. Ham Veri'!B2 -> 117010.9 | C4: ='1. Ham Veri'!C2 -> 98030.73 | D4: ='1. Ham Veri'!D2 -> 18980.173
A5: Dönem Sonu (Nis 2026) | B5: ='1. Ham Veri'!B95 -> 278734.33 | C5: ='1. Ham Veri'!C95 -> 243279.41 | D5: ='1. Ham Veri'!D95 -> 35454.923
A6: Mutlak Değişim | B6: =B5-B4 -> 161723.43 | C6: =C5-C4 -> 145248.68 | D6: =D5-D4 -> 16474.75
A7: Toplam Değişim (%) | B7: =(B5-B4)/B4*100 -> 138.21227 | C7: =(C5-C4)/C4*100 -> 148.16648 | D7: =(D5-D4)/D4*100 -> 86.799788
A8: Haftalık Ortalama Büyüme (%) | B8: =AVERAGE('1. Ham Veri'!G3:G95) -> 0.94795726
A9: En Yüksek Haftalık Artış (%) | B9: =MAX('1. Ham Veri'!G3:G95) -> 5.8964137
A10: En Yüksek Haftalık Düşüş (%) | B10: =MIN('1. Ham Veri'!G3:G95) -> -1.7764242
A13: Yıl | B13: Ort. Toplam | C13: Ort. TL | D13: Ort. YP
A14: 2024 | B14: =AVERAGEIF('1. Ham Veri'!E2:E95,2024,'1. Ham Veri'!B2:B95) -> 127294.63 | C14: =AVERAGEIF('1. Ham Veri'!E2:E95,2024,'1. Ham Veri'!C2:C95) -> 106924.34 | D14: =AVERAGEIF('1. Ham Veri'!E2:E95,2024,'1. Ham Veri'!D2:D95) -> 20370.286
A15: 2025 | B15: =AVERAGEIF('1. Ham Veri'!E2:E95,2025,'1. Ham Veri'!B2:B95) -> 189959.57 | C15: =AVERAGEIF('1. Ham Veri'!E2:E95,2025,'1. Ham Veri'!C2:C95) -> 162372 | D15: =AVERAGEIF('1. Ham Veri'!E2:E95,2025,'1. Ham Veri'!D2:D95) -> 27587.567
A16: 2026 | B16: =AVERAGEIF('1. Ham Veri'!E2:E95,2026,'1. Ham Veri'!B2:B95) -> 274502.06 | C16: =AVERAGEIF('1. Ham Veri'!E2:E95,2026,'1. Ham Veri'!C2:C95) -> 240662.2 | D16: =AVERAGEIF('1. Ham Veri'!E2:E95,2026,'1. Ham Veri'!D2:D95) -> 33839.865
A17: Yıllık Değişim 2024 -> 2025 (%) | B17: =(B15-B14)/B14*100 -> 49.228267 | C17: =(C15-C14)/C14*100 -> 51.85691 | D17: =(D15-D14)/D14*100 -> 35.430431
A18: Yıllık Değişim 2025 -> 2026 (%) | B18: =(B16-B15)/B15*100 -> 44.505522 | C18: =(C16-C15)/C15*100 -> 48.216563 | D18: =(D16-D15)/D15*100 -> 22.663465

Sheet 4. Mevsimsellik
A1: Finansman Şirketleri - Mevsimsellik Analizi
A3: Ay | B3: Ort. Toplam | C3: Ort. TL | D3: Ort. YP
A4: Ocak | B4: =AVERAGEIF('1. Ham Veri'!$F$2:$F$95,1,'1. Ham Veri'!$B$2:$B$95) -> 212859.05 | C4: =AVERAGEIF('1. Ham Veri'!$F$2:$F$95,1,'1. Ham Veri'!$C$2:$C$95) -> 185714.46 | D4: =AVERAGEIF('1. Ham Veri'!$F$2:$F$95,1,'1. Ham Veri'!$D$2:$D$95) -> 27144.597
A5: Şubat | B5: =AVERAGEIF('1. Ham Veri'!$F$2:$F$95,2,'1. Ham Veri'!$B$2:$B$95) -> 212860.89 | C5: =AVERAGEIF('1. Ham Veri'!$F$2:$F$95,2,'1. Ham Veri'!$C$2:$C$95) -> 185879.75 | D5: =AVERAGEIF('1. Ham Veri'!$F$2:$F$95,2,'1. Ham Veri'!$D$2:$D$95) -> 26981.146
A6: Mart | B6: =AVERAGEIF('1. Ham Veri'!$F$2:$F$95,3,'1. Ham Veri'!$B$2:$B$95) -> 217652.89 | C6: =AVERAGEIF('1. Ham Veri'!$F$2:$F$95,3,'1. Ham Veri'!$C$2:$C$95) -> 190196.02 | D6: =AVERAGEIF('1. Ham Veri'!$F$2:$F$95,3,'1. Ham Veri'!$D$2:$D$95) -> 27456.869
A7: Nisan | B7: =AVERAGEIF('1. Ham Veri'!$F$2:$F$95,4,'1. Ham Veri'!$B$2:$B$95) -> 205647.28 | C7: =AVERAGEIF('1. Ham Veri'!$F$2:$F$95,4,'1. Ham Veri'!$C$2:$C$95) -> 177707.62 | D7: =AVERAGEIF('1. Ham Veri'!$F$2:$F$95,4,'1. Ham Veri'!$D$2:$D$95) -> 27939.661
A8: Mayıs | B8: =AVERAGEIF('1. Ham Veri'!$F$2:$F$95,5,'1. Ham Veri'!$B$2:$B$95) -> 177100.82 | C8: =AVERAGEIF('1. Ham Veri'!$F$2:$F$95,5,'1. Ham Veri'!$C$2:$C$95) -> 150479.8 | D8: =AVERAGEIF('1. Ham Veri'!$F$2:$F$95,5,'1. Ham Veri'!$D$2:$D$95) -> 26621.024
A9: Haziran | B9: =AVERAGEIF('1. Ham Veri'!$F$2:$F$95,6,'1. Ham Veri'!$B$2:$B$95) -> 170559.63 | C9: =AVERAGEIF('1. Ham Veri'!$F$2:$F$95,6,'1. Ham Veri'!$C$2:$C$95) -> 143984.05 | D9: =AVERAGEIF('1. Ham Veri'!$F$2:$F$95,6,'1. Ham Veri'!$D$2:$D$95) -> 26575.578
A10: Temmuz | B10: =AVERAGEIF('1. Ham Veri'!$F$2:$F$95,7,'1. Ham Veri'!$B$2:$B$95) -> 154693.2 | C10: =AVERAGEIF('1. Ham Veri'!$F$2:$F$95,7,'1. Ham Veri'!$C$2:$C$95) -> 129354.67 | D10: =AVERAGEIF('1. Ham Veri'!$F$2:$F$95,7,'1. Ham Veri'!$D$2:$D$95) -> 25338.535
A11: Ağustos | B11: =AVERAGEIF('1. Ham Veri'!$F$2:$F$95,8,'1. Ham Veri'!$B$2:$B$95) -> 159409.69 | C11: =AVERAGEIF('1. Ham Veri'!$F$2:$F$95,8,'1. Ham Veri'!$C$2:$C$95) -> 133531.3 | D11: =AVERAGEIF('1. Ham Veri'!$F$2:$F$95,8,'1. Ham Veri'!$D$2:$D$95) -> 25878.39
A12: Eylül | B12: =AVERAGEIF('1. Ham Veri'!$F$2:$F$95,9,'1. Ham Veri'!$B$2:$B$95) -> 162824.57 | C12: =AVERAGEIF('1. Ham Veri'!$F$2:$F$95,9,'1. Ham Veri'!$C$2:$C$95) -> 136739.53 | D12: =AVERAGEIF('1. Ham Veri'!$F$2:$F$95,9,'1. Ham Veri'!$D$2:$D$95) -> 26085.04
A13: Ekim | B13: =AVERAGEIF('1. Ham Veri'!$F$2:$F$95,10,'1. Ham Veri'!$B$2:$B$95) -> 176872.7 | C13: =AVERAGEIF('1. Ham Veri'!$F$2:$F$95,10,'1. Ham Veri'!$C$2:$C$95) -> 150159.3 | D13: =AVERAGEIF('1. Ham Veri'!$F$2:$F$95,10,'1. Ham Veri'!$D$2:$D$95) -> 26713.395
A14: Kasım | B14: =AVERAGEIF('1. Ham Veri'!$F$2:$F$95,11,'1. Ham Veri'!$B$2:$B$95) -> 175948.2 | C14: =AVERAGEIF('1. Ham Veri'!$F$2:$F$95,11,'1. Ham Veri'!$C$2:$C$95) -> 150611.17 | D14: =AVERAGEIF('1. Ham Veri'!$F$2:$F$95,11,'1. Ham Veri'!$D$2:$D$95) -> 25337.038
A15: Aralık | B15: =AVERAGEIF('1. Ham Veri'!$F$2:$F$95,12,'1. Ham Veri'!$B$2:$B$95) -> 197233.68 | C15: =AVERAGEIF('1. Ham Veri'!$F$2:$F$95,12,'1. Ham Veri'!$C$2:$C$95) -> 170614.71 | D15: =AVERAGEIF('1. Ham Veri'!$F$2:$F$95,12,'1. Ham Veri'!$D$2:$D$95) -> 26618.964
A17: Ay | B17: Mevsimsel Endeks
A18: Ocak | B18: =B4/AVERAGE($B$4:$B$15)*100 -> 114.86943
A19: Şubat | B19: =B5/AVERAGE($B$4:$B$15)*100 -> 114.87043
A20: Mart | B20: =B6/AVERAGE($B$4:$B$15)*100 -> 117.45643
A21: Nisan | B21: =B7/AVERAGE($B$4:$B$15)*100 -> 110.9776
A22: Mayıs | B22: =B8/AVERAGE($B$4:$B$15)*100 -> 95.572496
A23: Haziran | B23: =B9/AVERAGE($B$4:$B$15)*100 -> 92.042539
A24: Temmuz | B24: =B10/AVERAGE($B$4:$B$15)*100 -> 83.48022
A25: Ağustos | B25: =B11/AVERAGE($B$4:$B$15)*100 -> 86.025473
A26: Eylül | B26: =B12/AVERAGE($B$4:$B$15)*100 -> 87.868312
A27: Ekim | B27: =B13/AVERAGE($B$4:$B$15)*100 -> 95.449389
A28: Kasım | B28: =B14/AVERAGE($B$4:$B$15)*100 -> 94.950487
A29: Aralık | B29: =B15/AVERAGE($B$4:$B$15)*100 -> 106.4372

Sheet 5. TL-YP Analizi
A1: Finansman Şirketleri - Korelasyon & TL/YP Ayrışma Analizi
A3: Korelasyon | B3: Toplam | C3: TL | D3: YP
A4: Toplam | B4: =1 -> 1 | C4: =CORREL('1. Ham Veri'!B2:B95,'1. Ham Veri'!C2:C95) -> 0.99908596 | D4: =CORREL('1. Ham Veri'!B2:B95,'1. Ham Veri'!D2:D95) -> 0.9338885
A5: TL | B5: =C4 -> 0.99908596 | C5: =1 -> 1 | D5: =CORREL('1. Ham Veri'!C2:C95,'1. Ham Veri'!D2:D95) -> 0.91775034
A6: YP | B6: =D4 -> 0.9338885 | C6: =D5 -> 0.91775034 | D6: =1 -> 1
A9: Dönem | B9: TL Payı (%) | C9: YP Payı (%)
A10: Dönem Başı (Haz 2024) | B10: ='1. Ham Veri'!H2 -> 83.779142 | C10: ='1. Ham Veri'!I2 -> 16.220858
A11: Dönem Sonu (Nis 2026) | B11: ='1. Ham Veri'!H95 -> 87.28003 | C11: ='1. Ham Veri'!I95 -> 12.71997
A12: Ortalama | B12: =AVERAGE('1. Ham Veri'!$H$2:$H$95) -> 85.390351 | C12: =AVERAGE('1. Ham Veri'!$I$2:$I$95) -> 14.609649
A13: Minimum | B13: =MIN('1. Ham Veri'!$H$2:$H$95) -> 82.748549 | C13: =MIN('1. Ham Veri'!$I$2:$I$95) -> 12.032579
A14: Maksimum | B14: =MAX('1. Ham Veri'!$H$2:$H$95) -> 87.967421 | C14: =MAX('1. Ham Veri'!$I$2:$I$95) -> 17.251451
A15: Değişim Puan | B15: =B11-B10 -> 3.5008887 | C15: =C11-C10 -> -3.5008887
A18: Yıl | B18: Ort. TL Payı (%) | C18: Ort. YP Payı (%) | D18: YP/TL Oranı
A19: 2024 | B19: =AVERAGEIF('1. Ham Veri'!$E$2:$E$95,2024,'1. Ham Veri'!$H$2:$H$95) -> 83.941208 | C19: =AVERAGEIF('1. Ham Veri'!$E$2:$E$95,2024,'1. Ham Veri'!$I$2:$I$95) -> 16.058792 | D19: =C19/B19 -> 0.19131
A20: 2025 | B20: =AVERAGEIF('1. Ham Veri'!$E$2:$E$95,2025,'1. Ham Veri'!$H$2:$H$95) -> 85.484358 | C20: =AVERAGEIF('1. Ham Veri'!$E$2:$E$95,2025,'1. Ham Veri'!$I$2:$I$95) -> 14.515642 | D20: =C20/B20 -> 0.16980465
A21: 2026 | B21: =AVERAGEIF('1. Ham Veri'!$E$2:$E$95,2026,'1. Ham Veri'!$H$2:$H$95) -> 87.672918 | C21: =AVERAGEIF('1. Ham Veri'!$E$2:$E$95,2026,'1. Ham Veri'!$I$2:$I$95) -> 12.327082 | D21: =C21/B21 -> 0.14060308

Sheet 6. Tahmin
A1: Tarih | B1: Toplam | C1: TL | D1: YP | F1: Tarih | G1: TL Fark | H1: YP Fark | M1: Tarih | N1: Toplam | O1: TL | P1: YP | Q1: TL Fark | R1: YP Park
A2: 45471 | B2: 117010.9 | C2: 98030.73 | D2: 18980.173 | F2: 45471 | M2: 45471 | N2: 117010.9 | O2: 98030.73 | P2: 18980.173
A3: 45478 | B3: 114932.29 | C3: 96041.429 | D3: 18890.864 | F3: 45478 | G3: =C3-C2 -> -1989.301 | H3: =D3-D2 -> -89.309 | M3: 45478 | N3: 114932.29 | O3: 96041.429 | P3: 18890.864 | Q3: =O3-O2 -> -1989.301 | R3: =P3-P2 -> -89.309
A4: 45485 | B4: 115625.71 | C4: 96172.502 | D4: 19453.208 | F4: 45485 | G4: =C4-C3 -> 131.073 | H4: =D4-D3 -> 562.344 | M4: 45485 | N4: 115625.71 | O4: 96172.502 | P4: 19453.208 | Q4: =O4-O3 -> 131.073 | R4: =P4-P3 -> 562.344
A5: 45492 | B5: 116662.35 | C5: 96978.198 | D5: 19684.157 | F5: 45492 | G5: =C5-C4 -> 805.696 | H5: =D5-D4 -> 230.949 | M5: 45492 | N5: 116662.35 | O5: 96978.198 | P5: 19684.157 | Q5: =O5-O4 -> 805.696 | R5: =P5-P4 -> 230.949
A6: 45499 | B6: 119109.59 | C6: 99718.083 | D6: 19391.502 | F6: 45499 | G6: =C6-C5 -> 2739.885 | H6: =D6-D5 -> -292.655 | M6: 45499 | N6: 119109.59 | O6: 99718.083 | P6: 19391.502 | Q6: =O6-O5 -> 2739.885 | R6: =P6-P5 -> -292.655
A7: 45506 | B7: 120109.59 | C7: 100379.91 | D7: 19729.672 | F7: 45506 | G7: =C7-C6 -> 661.83 | H7: =D7-D6 -> 338.17 | M7: 45506 | N7: 120109.59 | O7: 100379.91 | P7: 19729.672 | Q7: =O7-O6 -> 661.83 | R7: =P7-P6 -> 338.17
A8: 45513 | B8: 120407.13 | C8: 100152.51 | D8: 20254.622 | F8: 45513 | G8: =C8-C7 -> -227.402 | H8: =D8-D7 -> 524.95 | M8: 45513 | N8: 120407.13 | O8: 100152.51 | P8: 20254.622 | Q8: =O8-O7 -> -227.402 | R8: =P8-P7 -> 524.95
A9: 45520 | B9: 120243.96 | C9: 99771.962 | D9: 20471.995 | F9: 45520 | G9: =C9-C8 -> -380.549 | H9: =D9-D8 -> 217.373 | M9: 45520 | N9: 120243.96 | O9: 99771.962 | P9: 20471.995 | Q9: =O9-O8 -> -380.549 | R9: =P9-P8 -> 217.373
A10: 45527 | B10: 121657.74 | C10: 100670.01 | D10: 20987.725 | F10: 45527 | G10: =C10-C9 -> 898.05 | H10: =D10-D9 -> 515.73 | M10: 45527 | N10: 121657.74 | O10: 100670.01 | P10: 20987.725 | Q10: =O10-O9 -> 898.05 | R10: =P10-P9 -> 515.73
A11: 45534 | B11: 125053.04 | C11: 103837.22 | D11: 21215.821 | F11: 45534 | G11: =C11-C10 -> 3167.209 | H11: =D11-D10 -> 228.096 | M11: 45534 | N11: 125053.04 | O11: 103837.22 | P11: 21215.821 | Q11: =O11-O10 -> 3167.209 | R11: =P11-P10 -> 228.096
A12: 45541 | B12: 123406.05 | C12: 102457.94 | D12: 20948.108 | F12: 45541 | G12: =C12-C11 -> -1379.28 | H12: =D12-D11 -> -267.713 | M12: 45541 | N12: 123406.05 | O12: 102457.94 | P12: 20948.108 | Q12: =O12-O11 -> -1379.28 | R12: =P12-P11 -> -267.713
A13: 45548 | B13: 123318.52 | C13: 102559.99 | D13: 20758.531 | F13: 45548 | G13: =C13-C12 -> 102.052 | H13: =D13-D12 -> -189.577 | M13: 45548 | N13: 123318.52 | O13: 102559.99 | P13: 20758.531 | Q13: =O13-O12 -> 102.052 | R13: =P13-P12 -> -189.577
A14: 45555 | B14: 124025.6 | C14: 102934.88 | D14: 21090.723 | F14: 45555 | G14: =C14-C13 -> 374.887 | H14: =D14-D13 -> 332.192 | M14: 45555 | N14: 124025.6 | O14: 102934.88 | P14: 21090.723 | Q14: =O14-O13 -> 374.887 | R14: =P14-P13 -> 332.192
... A54: 45835 | B54: 187969.62 | C54: 158245.24 | D54: 29724.386 | F54: 45835 | G54: =C54-C53 -> 3614.501 | H54: =D54-D53 -> 1048.498 | M54: 45835 | N54: 187969.62 | O54: 158245.24 | P54: 29724.386 | Q54: =O54-O53 -> 3614.501 | R54: =P54-P53 -> 1048.498
A55: 45842 | B55: 193029.09 | C55: 161687.51 | D55: 31341.582 | F55: 45842 | G55: =_xlfn.FORECAST.ETS(F55,G3:G54,F3:F54) -> 1581.2958 | H55: =_xlfn.FORECAST.ETS(F55,H3:H54,F3:F54) -> 476.38299 | I55: =C54+G55 -> 159826.53 | J55: =D54+H55 -> 30200.769 | M55: 45842 | N55: 193029.09 | O55: 161687.51 | P55: 31341.582 | Q55: =O55-O54 -> 3442.27 | R55: =P55-P54 -> 1617.196
A56: 45849 | B56: 193187.67 | C56: 161742.35 | D56: 31445.323 | F56: 45849 | G56: =_xlfn.FORECAST.ETS(F56,G4:G55,F4:F55) -> 1646.1157 | H56: =_xlfn.FORECAST.ETS(F56,H4:H55,F4:F55) -> 530.59921 | I56: =C55+G56 -> 163333.62 | J56: =D55+H56 -> 31872.181 | M56: 45849 | N56: 193187.67 | O56: 161742.35 | P56: 31445.323 | Q56: =O56-O55 -> 54.84 | R56: =P56-P55 -> 103.741
A57: 45856 | B57: 192450.62 | C57: 161312.86 | D57: 31137.757 | F57: 45856 | G57: =_xlfn.FORECAST.ETS(F57,G5:G56,F5:F56) -> 1559.0453 | H57: =_xlfn.FORECAST.ETS(F57,H5:H56,F5:F56) -> 572.13292 | I57: =C56+G57 -> 163301.39 | J57: =D56+H57 -> 32017.456 | M57: 45856 | N57: 192450.62 | O57: 161312.86 | P57: 31137.757 | Q57: =O57-O56 -> -429.484 | R57: =P57-P56 -> -307.566
A58: 45863 | B58: 192548.3 | C58: 161184.41 | D58: 31363.887 | F58: 45863 | G58: =_xlfn.FORECAST.ETS(F58,G6:G57,F6:F57) -> 1374.6745 | H58: =_xlfn.FORECAST.ETS(F58,H6:H57,F6:F57) -> 574.66216 | I58: =C57+G58 -> 162687.54 | J58: =D57+H58 -> 31712.419 | M58: 45863 | N58: 192548.3 | O58: 161184.41 | P58: 31363.887 | Q58: =O58-O57 -> -128.454 | R58: =P58-P57 -> 226.13
A59: 45870 | B59: 196259.36 | C59: 165558.44 | D59: 30700.915 | F59: 45870 | G59: =_xlfn.FORECAST.ETS(F59,G7:G58,F7:F58) -> 1648.2682 | H59: =_xlfn.FORECAST.ETS(F59,H7:H58,F7:F58) -> 604.78759 | I59: =C58+G59 -> 162832.68 | J59: =D58+H59 -> 31968.675 | M59: 45870 | N59: 196259.36 | O59: 165558.44 | P59: 30700.915 | Q59: =O59-O58 -> 4374.031 | R59: =P59-P58 -> -662.972
A60: 45877 | B60: 196486.32 | C60: 164995.61 | D60: 31490.715 | F60: 45877 | G60: =_xlfn.FORECAST.ETS(F60,G8:G59,F8:F59) -> 1629.1328 | H60: =_xlfn.FORECAST.ETS(F60,H8:H59,F8:F59) -> 612.96762 | I60: =C59+G60 -> 167187.57 | J60: =D59+H60 -> 31313.883 | M60: 45877 | N60: 196486.32 | O60: 164995.61 | P60: 31490.715 | Q60: =O60-O59 -> -562.834 | R60: =P60-P59 -> 789.8
A61: 45884 | B61: 197524.31 | C61: 166037.28 | D61: 31487.028 | F61: 45884 | G61: =_xlfn.FORECAST.ETS(F61,G9:G60,F9:F60) -> 1643.1115 | H61: =_xlfn.FORECAST.ETS(F61,H9:H60,F9:F60) -> 639.84185 | I61: =C60+G61 -> 166638.72 | J61: =D60+H61 -> 32130.557 | M61: 45884 | N61: 197524.31 | O61: 166037.28 | P61: 31487.028 | Q61: =O61-O60 -> 1041.675 | R61: =P61-P60 -> -3.687
A62: 45891 | B62: 196372.31 | C62: 165052.07 | D62: 31320.234 | F62: 45891 | G62: =_xlfn.FORECAST.ETS(F62,G10:G61,F10:F61) -> 1564.9274 | H62: =_xlfn.FORECAST.ETS(F62,H10:H61,F10:F61) -> 650.23366 | I62: =C61+G62 -> 167602.21 | J62: =D61+H62 -> 32137.262 | M62: 45891 | N62: 196372.31 | O62: 165052.07 | P62: 31320.234 | Q62: =O62-O61 -> -985.209 | R62: =P62-P61 -> -166.794
A63: 45898 | B63: 199983.14 | C63: 168857.97 | D63: 31125.173 | F63: 45898 | G63: =_xlfn.FORECAST.ETS(F63,G11:G62,F11:F62) -> 1399.7102 | H63: =_xlfn.FORECAST.ETS(F63,H11:H62,F11:F62) -> 682.22261 | I63: =C62+G63 -> 166451.78 | J63: =D62+H63 -> 32002.457 | M63: 45898 | N63: 199983.14 | O63: 168857.97 | P63: 31125.173 | Q63: =O63-O62 -> 3805.897 | R63: =P63-P62 -> -195.061
A64: 45905 | B64: 198410.08 | C64: 167426.73 | D64: 30983.348 | F64: 45905 | G64: =_xlfn.FORECAST.ETS(F64,G12:G63,F12:F63) -> 1689.7483 | H64: =_xlfn.FORECAST.ETS(F64,H12:H63,F12:F63) -> 754.57035 | I64: =C63+G64 -> 170547.72 | J64: =D63+H64 -> 31879.743 | M64: 45905 | N64: 198410.08 | O64: 167426.73 | P64: 30983.348 | Q64: =O64-O63 -> -1431.237 | R64: =P64-P63 -> -141.825
A65: 45912 | B65: 198778.49 | C65: 167680.06 | D65: 31098.434 | F65: 45912 | G65: =_xlfn.FORECAST.ETS(F65,G13:G64,F13:F64) -> 3261.0892 | H65: =_xlfn.FORECAST.ETS(F65,H13:H64,F13:F64) -> 763.63875 | I65: =C64+G65 -> 170687.82 | J65: =D64+H65 -> 31746.987 | M65: 45912 | N65: 198778.49 | O65: 167680.06 | P65: 31098.434 | Q65: =O65-O64 -> 253.323 | R65: =P65-P64 -> 115.086
A66: 45919 | B66: 202137.93 | C66: 170914.61 | D66: 31223.315 | F66: 45919 | G66: =_xlfn.FORECAST.ETS(F66,G14:G65,F14:F65) -> 2782.3567 | H66: =_xlfn.FORECAST.ETS(F66,H14:H65,F14:F65) -> 736.84312 | I66: =C65+G66 -> 170462.41 | J66: =D65+H66 -> 31835.277 | M66: 45919 | N66: 202137.93 | O66: 170914.61 | P66: 31223.315 | Q66: =O66-O65 -> 3234.555 | R66: =P66-P65 -> 124.881
... A95: 46122 | B95: 278734.33 | C95: 243279.41 | D95: 35454.923 | F95: 46122 | G95: =_xlfn.FORECAST.ETS(F95,G43:G94,F43:F94) -> 3188.4518 | H95: =_xlfn.FORECAST.ETS(F95,H43:H94,F43:F94) -> 1173.516 | I95: =C94+G95 -> 247438.76 | J95: =D94+H95 -> 36231.47 | M95: 46122 | N95: 278734.33 | O95: 243279.41 | P95: 35454.923 | Q95: =O95-O94 -> -970.896 | R95: =P95-P94 -> 396.969
L96: Tahmin | M96: 46129 | N96: =O96+P96 -> 280590.09 | O96: =O95+Q96 -> 244900.09 | P96: =P95+R96 -> 35689.998 | Q96: =_xlfn.FORECAST.ETS(M96,Q3:Q95,M3:M95) -> 1620.6771 | R96: =_xlfn.FORECAST.ETS(M96,R3:R95,M3:M95) -> 235.07494
M97: 46136 | N97: =O97+P97 -> 284013.87 | O97: =O96+Q97 -> 248087.66 | P97: =P96+R97 -> 35926.208 | Q97: =_xlfn.FORECAST.ETS(M97,Q4:Q96,M4:M96) -> 3187.5761 | R97: =_xlfn.FORECAST.ETS(M97,R4:R96,M4:M96) -> 236.21041
M98: 46143 | N98: =O98+P98 -> 286865.16 | O98: =O97+Q98 -> 250701.59 | P98: =P97+R98 -> 36163.567 | Q98: =_xlfn.FORECAST.ETS(M98,Q5:Q97,M5:M97) -> 2613.9273 | R98: =_xlfn.FORECAST.ETS(M98,R5:R97,M5:M97) -> 237.35836
M99: 46150 | N99: =O99+P99 -> 289759.72 | O99: =O98+Q99 -> 253329.65 | P99: =P98+R99 -> 36430.068 | Q99: =_xlfn.FORECAST.ETS(M99,Q6:Q98,M6:M98) -> 2628.061 | R99: =_xlfn.FORECAST.ETS(M99,R6:R98,M6:M98) -> 266.50167
M100: 46157 | N100: =O100+P100 -> 292834.44 | O100: =O99+Q100 -> 256136.91 | P100: =P99+R100 -> 36697.529 | Q100: =_xlfn.FORECAST.ETS(M100,Q7:Q99,M7:M99) -> 2807.2607 | R100: =_xlfn.FORECAST.ETS(M100,R7:R99,M7:M99) -> 267.4605
M101: 46164 | N101: =O101+P101 -> 296745.58 | O101: =O100+Q101 -> 259779.47 | P101: =P100+R101 -> 36966.115 | Q101: =_xlfn.FORECAST.ETS(M101,Q8:Q100,M8:M100) -> 3642.552 | R101: =_xlfn.FORECAST.ETS(M101,R8:R100,M8:M100) -> 268.58583
M102: 46171 | N102: =O102+P102 -> 300834.61 | O102: =O101+Q102 -> 263598.48 | P102: =P101+R102 -> 37236.125 | Q102: =_xlfn.FORECAST.ETS(M102,Q9:Q101,M9:M101) -> 3819.0155 | R102: =_xlfn.FORECAST.ETS(M102,R9:R101,M9:M101) -> 270.01046
M103: 46178 | N103: =O103+P103 -> 303811.66 | O103: =O102+Q103 -> 266304.01 | P103: =P102+R103 -> 37507.649 | Q103: =_xlfn.FORECAST.ETS(M103,Q10:Q102,M10:M102) -> 2705.5259 | R103: =_xlfn.FORECAST.ETS(M103,R10:R102,M10:M102) -> 271.52351
M104: 46185 | N104: =O104+P104 -> 306937.41 | O104: =O103+Q104 -> 269156.43 | P104: =P103+R104 -> 37780.983 | Q104: =_xlfn.FORECAST.ETS(M104,Q11:Q103,M11:M103) -> 2852.4193 | R104: =_xlfn.FORECAST.ETS(M104,R11:R103,M11:M103) -> 273.33444
M105: 46192 | N105: =O105+P105 -> 310143.17 | O105: =O104+Q105 -> 272077.01 | P105: =P104+R105 -> 38066.161 | Q105: =_xlfn.FORECAST.ETS(M105,Q12:Q104,M12:M104) -> 2920.5825 | R105: =_xlfn.FORECAST.ETS(M105,R12:R104,M12:M104) -> 285.17773
M106: 46199 | N106: =O106+P106 -> 313346.66 | O106: =O105+Q106 -> 275002.08 | P106: =P105+R106 -> 38344.578 | Q106: =_xlfn.FORECAST.ETS(M106,Q13:Q105,M13:M105) -> 2925.0765 | R106: =_xlfn.FORECAST.ETS(M106,R13:R105,M13:M105) -> 278.41752
M107: 46206 | N107: =O107+P107 -> 316113.98 | O107: =O106+Q107 -> 277660.01 | P107: =P106+R107 -> 38453.973 | Q107: =_xlfn.FORECAST.ETS(M107,Q14:Q106,M14:M106) -> 2657.9245 | R107: =_xlfn.FORECAST.ETS(M107,R14:R106,M14:M106) -> 109.39492
...
